Workbook

Sheet Position
H1: Category | I1: Ticker | J1: Name | K1: Qty | L1: Multiplier | M1: Price | N1: Exposure(USD) | O1: Type | P1: duration (FUT_EQV_MOD_DUR_BASED_ON_CTD) | Q1: FI Exposure (10Y eqv) | R1: Dollar% | S1: FX | T1: Expected Vol | U1: Vol Contribution
A2: Summary | B2: %funded | C2: =(SUMIF(O:O,"ETF",N:N))/C3 -> 0.93671749 | H2: DMEQ | I2: SPY | J2: US | K2: 100 | L2: 1 | M2: =IFERROR(__xludf.DUMMYFUNCTION("GOOGLEFINANCE(I2, ""price"")"),656.82) -> 656.82 | N2: =K2*L2*M2*S2 -> 65682 | O2: ETF | P2: 1 | R2: =N2/$C$3 -> 0.08527188 | S2: 1 | T2: 0.15 | U2: =N2/$C$3*T2 -> 0.012790782
B3: $AUM | C3: =SUMIF(O:O,"<>Futures",N:N) -> 770265.65 | H3: DMEQ | I3: VOO | J3: US | K3: 155 | L3: 1 | M3: =IFERROR(__xludf.DUMMYFUNCTION("GOOGLEFINANCE(I3, ""price"")"),605.66) -> 605.66 | N3: =K3*L3*M3*S3 -> 93877.3 | O3: ETF | P3: 1 | R3: =N3/$C$3 -> 0.12187652 | S3: 1 | T3: 0.15 | U3: =N3/$C$3*T3 -> 0.018281479
B4: S$ AUM | C4: =C3/J48 -> 987634.61 | H4: DMEQ | I4: LON:SPYL | J4: US | K4: 4000 | L4: 1 | M4: =IFERROR(__xludf.DUMMYFUNCTION("GOOGLEFINANCE(I4, ""price"")"),16.26) -> 16.26 | N4: =K4*L4*M4*S4 -> 65040 | O4: ETF | P4: 1 | R4: =N4/$C$3 -> 0.084438402 | S4: 1 | T4: 0.18 | U4: =N4/$C$3*T4 -> 0.015198912
H5: DMEQ | I5: SOXX | J5: US | K5: 60 | L5: 1 | M5: =IFERROR(__xludf.DUMMYFUNCTION("GOOGLEFINANCE(I5, ""price"")"),345.25) -> 345.25 | N5: =K5*L5*M5*S5 -> 20715 | O5: ETF | P5: 1 | R5: =N5/$C$3 -> 0.026893319 | S5: 1 | T5: 0.18 | U5: =N5/$C$3*T5 -> 0.0048407975
A6: Dollar Allocation | B6: $ | C6: Dollar% | D6: vol contr | E6: Wt in ACWI | H6: DMEQ | I6: TSLA | J6: TSLA | K6: 15 | L6: 1 | M6: =IFERROR(__xludf.DUMMYFUNCTION("GOOGLEFINANCE(I6, ""price"")"),385.95) -> 385.95 | N6: =K6*L6*M6*S6 -> 5789.25 | O6: ETF | P6: 1 | R6: =N6/$C$3 -> 0.0075159135 | S6: 1 | T6: 0.25 | U6: =N6/$C$3*T6 -> 0.0018789784
A7: DMEQ | B7: =SUMIF(H:H,A7,N:N)+E7*SUMIF(H:H,"EQ",N:N) -> 448015.13 | C7: =B7/$C$3 -> 0.58163717 | D7: =SUMIF(H:H,A7,U:U) -> 0.076532048 | E7: 0.89 | H7: DMEQ | I7: IEUR | J7: EU | K7: 1000 | L7: 1 | M7: =IFERROR(__xludf.DUMMYFUNCTION("GOOGLEFINANCE(I7, ""price"")"),69.71) -> 69.71 | N7: =K7*L7*M7*S7 -> 69710 | O7: ETF | P7: 1 | R7: =N7/$C$3 -> 0.090501245 | S7: 1 | T7: 0.15 | U7: =N7/$C$3*T7 -> 0.013575187
A8: EMEQ | B8: =SUMIF(H:H,A8,N:N)+E8*SUMIF(H:H,"EQ",N:N) -> 118197.67 | C8: =B8/$C$3 -> 0.15345053 | D8: =SUMIF(H:H,A8,U:U) -> 0.031276807 | E8: 0.11 | H8: DMEQ | I8: VEA | J8: DM | K8: 800 | L8: 1 | M8: =IFERROR(__xludf.DUMMYFUNCTION("GOOGLEFINANCE(I8, ""price"")"),63.97) -> 63.97 | N8: =K8*L8*M8*S8 -> 51176 | O8: ETF | P8: 1 | R8: =N8/$C$3 -> 0.066439416 | S8: 1 | T8: 0.15 | U8: =N8/$C$3*T8 -> 0.0099659125
A9: EQ | B9: =SUM(B7:B8) -> 566212.8 | C9: =SUM(C7:C8) -> 0.7350877 | D9: =SUM(D7:D8) -> 0.10780886
A10: FI | B10: =SUMIF(H:H,A10,Q:Q) -> 709617.23 | C10: =B10/$C$3 -> 0.92126298 | D10: =SUMIF(H:H,A10,U:U) -> 0.068671296 | H10: EMEQ | I10: LON:XMME | J10: EM | K10: 200 | L10: 1 | M10: =IFERROR(__xludf.DUMMYFUNCTION("GOOGLEFINANCE(I10, ""price"")"),79.51) -> 79.51 | N10: =K10*L10*M10*S10 -> 15902 | O10: ETF | P10: 1 | R10: =N10/$C$3 -> 0.020644826 | S10: 1 | T10: 0.2 | U10: =N10/$C$3*T10 -> 0.0041289651
A11: GOLD | B11: =SUMIF(H:H,A11,N:N) -> 62443.5 | C11: =B11/$C$3 -> 0.081067487 | D11: =SUMIF(H:H,A11,U:U) -> 0.016213497 | H11: EMEQ | I11: FLKR | J11: KR | K11: 400 | L11: 1 | M11: =IFERROR(__xludf.DUMMYFUNCTION("GOOGLEFINANCE(I11, ""price"")"),41.41) -> 41.41 | N11: =K11*L11*M11*S11 -> 16564 | O11: ETF | P11: 1 | R11: =N11/$C$3 -> 0.021504269 | S11: 1 | T11: 0.2 | U11: =N11/$C$3*T11 -> 0.0043008539
A12: CM | B12: {=SUM(IF(H:H=A12,ABS(N:N)))} -> 15128 | C12: =B12/$C$3 -> 0.019639978 | D12: =SUMIF(H:H,A12,U:U) -> 0.0068739921 | H12: EMEQ | I12: KWEB | J12: China | K12: 1600 | L12: 1 | M12: =IFERROR(__xludf.DUMMYFUNCTION("GOOGLEFINANCE(I12, ""price"")"),29.14) -> 29.14 | N12: =K12*L12*M12*S12 -> 46624 | O12: ETF | P12: 1 | R12: =N12/$C$3 -> 0.060529767 | S12: 1 | T12: 0.25 | U12: =N12/$C$3*T12 -> 0.015132442
A13: CASH | B13: =SUMIF(H:H,A13,N:N) -> 48744.346 | C13: =B13/$C$3 -> 0.063282513 | D13: =SUMIF(H:H,A13,U:U) -> 0 | H13: EMEQ | I13: ASHR | J13: China | K13: 100 | L13: 1 | M13: =IFERROR(__xludf.DUMMYFUNCTION("GOOGLEFINANCE(I13, ""price"")"),32.7) -> 32.7 | N13: =K13*L13*M13*S13 -> 3270 | O13: ETF | P13: 1 | R13: =N13/$C$3 -> 0.0042452886 | S13: 1 | T13: 0.2 | U13: =N13/$C$3*T13 -> 0.00084905773
A14: Macro | B14: =SUMIF(H:H,A14,N:N) -> 34245 | C14: =B14/$C$3 -> 0.044458688 | D14: =SUMIF(H:H,A14,U:U) -> 0.0088917376 | H14: EMEQ | I14: IEMG | J14: EM | K14: 375 | L14: 1 | M14: =IFERROR(__xludf.DUMMYFUNCTION("GOOGLEFINANCE(I14, ""price"")"),70.51) -> 70.51 | N14: =K14*L14*M14*S14 -> 26441.25 | O14: ETF | P14: 1 | R14: =N14/$C$3 -> 0.034327443 | S14: 1 | T14: 0.2 | U14: =N14/$C$3*T14 -> 0.0068654886
H15: EQ | I15: LON:ACWD | J15: ACWI | K15: 300 | L15: 1 | M15: =IFERROR(__xludf.DUMMYFUNCTION("GOOGLEFINANCE(I15, ""price"")"),284.74) -> 284.74 | N15: =K15*L15*M15*S15 -> 85422 | O15: ETF | P15: 1 | R15: =N15/$C$3 -> 0.1108994 | S15: 1 | T15: 0.15 | U15: =N15/$C$3*T15 -> 0.01663491
A16: Total (corr=0) | D16: =SQRT(SUMPRODUCT(D9:D13,D9:D13)) -> 0.12902955
A17: Total (corr=1) | D17: =SUM(D9:D13) -> 0.19956764 | H17: CASH | I17: CASH (SGD value) | J17: Cash | K17: 62500 | L17: 1 | M17: 1 | N17: =K17*L17*M17*S17 -> 48744.346 | O17: CASH | P17: 1 | S17: =J48 -> 0.77990953 | T17: 0 | U17: =N16/$C$3*T16 -> 0
A18: Avg Est. | D18: =(D17+D16)/2 -> 0.1642986 | H18: CASH | I18: BOXX | J18: Cash | K18: 0 | L18: 1 | M18: =IFERROR(__xludf.DUMMYFUNCTION("GOOGLEFINANCE(I18, ""price"")"),116.06) -> 116.06 | N18: =K18*L18*M18*S18 -> 0 | O18: CASH | P18: 1 | R18: =N18/$C$3 -> 0 | S18: 1 | T18: 0 | U18: =N17/$C$3*T17 -> 0
A20: Inception Date | B20: 45722 | H20: FI | I20: DHB | J20: IG Duration-Hedged CR | K20: 0 | L20: 500 | M20: 218.6 | N20: =K20*L20*M20*S20 -> 0 | O20: Futures | P20: 0 | Q20: =N20*P20/$P$24 -> 0 | R20: =Q20/$C$3 -> 0 | S20: 1 | T20: 0.04 | U20: =N18/$C$3*T18 -> 0
B21: USD | C21: SGD | H21: FI | I21: HYG | J21: CR | K21: 0 | L21: 1 | M21: =IFERROR(__xludf.DUMMYFUNCTION("GOOGLEFINANCE(I21, ""price"")"),79.42) -> 79.42 | N21: =K21*L21*M21*S21 -> 0 | O21: ETF | P21: 8.379 | Q21: =N21*P21/$P$24 -> 0 | R21: =N21/$C$3 -> 0 | S21: 1 | T21: 0.07 | U21: =N20/$C$3*T20 -> 0
A22: Cost Basis | B22: =319067-23999/1.3459+95000/1.3092+104193/1.2851+188888*0.78+11112/1.3078+0.77*20000+43000+54898.73 -> 724005.03 | C22: =788888+11112+20000+55158+70000 -> 945158 | H22: FI | I22: LQD | J22: CR | K22: 400 | L22: 1 | M22: =IFERROR(__xludf.DUMMYFUNCTION("GOOGLEFINANCE(I22, ""price"")"),108.73) -> 108.73 | N22: =K22*L22*M22*S22 -> 43492 | O22: ETF | P22: 8.379 | Q22: =N22*P22/$P$24 -> 47780.185 | R22: =N22/$C$3 -> 0.056463637 | S22: 1 | T22: 0.07 | U22: =N21/$C$3*T21 -> 0
A23: $PNL | B23: =C3-B22 -> 46260.62 | C23: =C4-C22 -> 42476.611 | H23: FI | I23: TLT | J23: FI | K23: 0 | L23: 1 | M23: =IFERROR(__xludf.DUMMYFUNCTION("GOOGLEFINANCE(I23, ""price"")"),86.84) -> 86.84 | N23: =K23*L23*M23*S23 -> 0 | O23: ETF | P23: 15.95 | Q23: =N23*P23/$P$24 -> 0 | R23: =N23/$C$3 -> 0 | S23: 1 | T23: 0 | U23: =N22/$C$3*T22 -> 0.0039524546
A24: %PNL | B24: =B23/B22 -> 0.06389544 | C24: =C23/C22 -> 0.044941281 | H24: FI | I24: ZNW00:CBOT | J24: 10Y TF | K24: 1 | L24: 1000 | M24: =IFERROR(__xludf.DUMMYFUNCTION("IMPORTXML(""https://www.google.com/finance/quote/""&I24&""?hl=en"", ""//div[@class='YMlKec fxKbKc']"")"),110.69) -> 110.69 | N24: =K24*L24*M24*S24 -> 110690 | O24: Futures | P24: 7.627 | Q24: =N24*P24/$P$24 -> 110690 | R24: =Q24/$C$3 -> 0.14370367 | S24: 1 | T24: 0.07 | U24: =N23/$C$3*T23 -> 0
H25: FI | I25: ZFW00:CBOT | J25: 5Y TF | K25: 4 | L25: 1000 | M25: =IFERROR(__xludf.DUMMYFUNCTION("IMPORTXML(""https://www.google.com/finance/quote/""&I25&""?hl=en"", ""//div[@class='YMlKec fxKbKc']"")"),107.86) -> 107.86 | N25: =K25*L25*M25*S25 -> 431440 | O25: Futures | P25: 4.333 | Q25: =N25*P25/$P$24 -> 245106.79 | R25: =Q25/$C$3 -> 0.31821073 | S25: 1 | T25: 0.04 | U25: =N24/$C$3*T24 -> 0.010059257
H26: FI | I26: ZTW00:CBOT | J26: 2Y TF | K26: 6 | L26: 2000 | M26: =IFERROR(__xludf.DUMMYFUNCTION("IMPORTXML(""https://www.google.com/finance/quote/""&I26&""?hl=en"", ""//div[@class='YMlKec fxKbKc']"")"),103.52) -> 103.52 | N26: =K26*L26*M26*S26 -> 1242240 | O26: Futures | P26: 1.879 | Q26: =N26*P26/$P$24 -> 306040.25 | R26: =Q26/$C$3 -> 0.39731779 | S26: 1 | T26: 0.02 | U26: =N25/$C$3*T25 -> 0.022404738
A27: Year | B27: Return % | C27: Return $ | H27: FI | I27: BTP | J27: 10Y Italy | K27: 0 | L27: 1000 | M27: 119.28 | N27: =K27*L27*M27*S27 -> 0 | O27: Futures | P27: 8.061 | Q27: =N27*P27/$P$24 -> 0 | R27: =Q27/$C$3 -> 0 | S27: =J47 -> 1.157155 | T27: 0.07 | U27: =N26/$C$3*T26 -> 0.032254846
A28: 2025 (from March) | B28: 0.121 | C28: 80000 | H28: FI | I28: BTS | J28: 2Y Italy | K28: 0 | L28: 1000 | M28: 108.075 | N28: =K28*L28*M28*S28 -> 0 | O28: Futures | P28: 2 | Q28: =N28*P28/$P$24 -> 0 | R28: =Q28/$C$3 -> 0 | S28: =J47 -> 1.157155 | T28: 0.02 | U28: =N27/$C$3*T27 -> 0
A29: 2026 Till Now | B29: =C29/(C4-C29) -> -0.036602542 | C29: =C23-SUM(C$28:C28) -> -37523.389 | H29: FI | I29: OAT | J29: 10Y France | K29: 0 | L29: 1000 | M29: 120.65 | N29: =K29*L29*M29*S29 -> 0 | O29: Futures | P29: 7.929 | Q29: =N29*P29/$P$24 -> 0 | R29: =Q29/$C$3 -> 0 | S29: =J47 -> 1.157155 | T29: 0.07 | U29: =N28/$C$3*T28 -> 0
H30: FI | I30: G | J30: 10Y UK | K30: 0 | L30: 1000 | M30: 90.48 | N30: =K30*L30*M30*S30 -> 0 | O30: Futures | P30: 8.068 | Q30: =N30*P30/$P$24 -> 0 | R30: =Q30/$C$3 -> 0 | S30: =J49 -> 1.3367 | T30: 0.07 | U30: =N29/$C$3*T29 -> 0
H31: FI | I31: XM | J31: 10Y AU | K31: 0 | L31: 10000 | M31: 95.655 | N31: =K31*L31*M31*S31 -> 0 | O31: Futures | P31: 1 | Q31: =N31*P31/$P$24 -> 0 | R31: =Q31/$C$3 -> 0 | S31: =J50 -> 0.6951 | T31: 0.01 | U31: =N30/$C$3*T30 -> 0
H33: GOLD | I33: GLD | J33: Gold | K33: 150 | L33: 1 | M33: =IFERROR(__xludf.DUMMYFUNCTION("GOOGLEFINANCE(I33, ""price"")"),416.29) -> 416.29 | N33: =K33*L33*M33*S33 -> 62443.5 | O33: ETF | P33: 1 | R33: =N33/$C$3 -> 0.081067487 | S33: 1 | T33: 0.2 | U33: =N33/$C$3*T33 -> 0.016213497
H34: GOLD | I34: SLV | J34: Silver | K34: 0 | L34: 1 | M34: =IFERROR(__xludf.DUMMYFUNCTION("GOOGLEFINANCE(I34, ""price"")"),65.21) -> 65.21 | N34: =K34*L34*M34*S34 -> 0 | O34: ETF | P34: 1 | R34: =N34/$C$3 -> 0 | S34: 1 | T34: 0.2 | U34: =N34/$C$3*T34 -> 0
H35: GOLD | I35: GDX | J35: Gold Miner | K35: 0 | L35: 1 | M35: =IFERROR(__xludf.DUMMYFUNCTION("GOOGLEFINANCE(I35, ""price"")"),86.32) -> 86.32 | N35: =K35*L35*M35*S35 -> 0 | O35: ETF | P35: 1 | R35: =N35/$C$3 -> 0 | S35: 1 | T35: 0.35 | U35: =N35/$C$3*T35 -> 0
H36: CM | I36: COPX | J36: Copper Miner | K36: 200 | L36: 1 | M36: =IFERROR(__xludf.DUMMYFUNCTION("GOOGLEFINANCE(I36, ""price"")"),75.64) -> 75.64 | N36: =K36*L36*M36*S36 -> 15128 | O36: ETF | P36: 1 | R36: =N36/$C$3 -> 0.019639978 | S36: 1 | T36: 0.35 | U36: =N36/$C$3*T36 -> 0.0068739921
H37: CM | I37: CLZ5 | J37: CL | K37: 0 | L37: 100 | M37: =IFERROR(__xludf.DUMMYFUNCTION("IMPORTXML(""https://www.google.com/finance/quote/CLW00:NYMEX?hl=en"", ""//div[@class='YMlKec fxKbKc']"")"),91.74) -> 91.74 | N37: =K37*L37*M37*S37 -> 0 | O37: Futures | P37: 1 | R37: =N37/$C$3 -> 0 | S37: 1 | T37: 0.3 | U37: =N37/$C$3*T37 -> 0
H38: CM | I38: NGK26_NGQ26 | J38: NG | K38: 0 | L38: 10000 | M38: =IFERROR(__xludf.DUMMYFUNCTION("IMPORTXML(""https://www.google.com/finance/quote/NGW00:NYMEX?hl=en"", ""//div[@class='YMlKec fxKbKc']"")"),2.92) -> 2.92 | N38: =K38*L38*M38*S38 -> 0 | O38: Futures | P38: 1 | R38: =N38/$C$3 -> 0 | S38: 1 | T38: 0.3 | U38: =ABS(N38)/$C$3*T38 -> 0
H39: CM | I39: NGF26_NGJ26 | J39: NG | K39: 0 | L39: 10000 | M39: =IFERROR(__xludf.DUMMYFUNCTION("IMPORTXML(""https://www.google.com/finance/quote/NGW00:NYMEX?hl=en"", ""//div[@class='YMlKec fxKbKc']"")"),2.92) -> 2.92 | N39: =K39*L39*M39*S39 -> 0 | O39: Futures | P39: 1 | R39: =N39/$C$3 -> 0 | S39: 1 | T39: 0.3 | U39: =N39/$C$3*T39 -> 0
H41: Macro | I41: LON:DBMF | J41: Trend | K41: 200 | L41: 1 | M41: =IFERROR(__xludf.DUMMYFUNCTION("GOOGLEFINANCE(I41, ""price"")"),126.36) -> 126.36 | N41: =K41*L41*M41*S41 -> 25272 | O41: ETF | P41: 1 | R41: =N41/$C$3 -> 0.03280946 | S41: 1 | T41: 0.2 | U41: =N41/$C$3*T41 -> 0.006561892
H42: Macro | I42: DBMF | J42: Trend | K42: 300 | L42: 1 | M42: =IFERROR(__xludf.DUMMYFUNCTION("GOOGLEFINANCE(I42, ""price"")"),29.91) -> 29.91 | N42: =K42*L42*M42*S42 -> 8973 | O42: ETF | P42: 1 | R42: =N42/$C$3 -> 0.011649228 | S42: 1 | T42: 0.2 | U42: =N42/$C$3*T42 -> 0.0023298456
J46: FX
...

Sheet Risk
D1: 31 | E1: 92 | F1: 365 | G1: =365*5+1 -> 1826
C2: Latest | D2: 1M_AVG | E2: 3M_AVG | F2: 1Y_AVG | G2: 5Y_AVG | H2: EST | I2: Tail | K2: daily move
A3: EQ | B3: INDEXCBOE:VIX | C3: =IFERROR(__xludf.DUMMYFUNCTION("INDEX(GOOGLEFINANCE(B3,""close"",TODAY()-10,TODAY()),ROWS(GOOGLEFINANCE(B3,""close"",TODAY()-10,TODAY())),2) "),26.95) -> 26.95 | D3: =IFERROR(__xludf.DUMMYFUNCTION("AVERAGE(QUERY(GOOGLEFINANCE($B3,""close"",TODAY()-D$1,TODAY()),""select Col2 offset 1"",0))"),23.655909090909) -> 23.655909 | E3: =IFERROR(__xludf.DUMMYFUNCTION("AVERAGE(QUERY(GOOGLEFINANCE($B3,""close"",TODAY()-E$1,TODAY()),""select Col2 offset 1"",0))"),19.3091803278688) -> 19.30918 | F3: =IFERROR(__xludf.DUMMYFUNCTION("AVERAGE(QUERY(GOOGLEFINANCE($B3,""close"",TODAY()-F$1,TODAY()),""select Col2 offset 1"",0))"),19.2438399999999) -> 19.24384 | G3: =IFERROR(__xludf.DUMMYFUNCTION("AVERAGE(QUERY(GOOGLEFINANCE($B3,""close"",TODAY()-G$1,TODAY()),""select Col2 offset 1"",0))"),19.1748363926576) -> 19.174836 | H3: =SQRT(D3*E3) -> 21.372324 | I3: 40 | J3: % | K3: =H3/SQRT(255) -> 1.3383868
A4: FI | B4: INDEXNYSEGIS:MOVE | C4: =IFERROR(__xludf.DUMMYFUNCTION("INDEX(GOOGLEFINANCE(B4,""close"",TODAY()-10,TODAY()),ROWS(GOOGLEFINANCE(B4,""close"",TODAY()-10,TODAY())),2) "),103.01) -> 103.01 | D4: =IFERROR(__xludf.DUMMYFUNCTION("AVERAGE(QUERY(GOOGLEFINANCE($B4,""close"",TODAY()-D$1,TODAY()),""select Col2 offset 1"",0))"),80.5254545454545) -> 80.525455 | E4: =IFERROR(__xludf.DUMMYFUNCTION("AVERAGE(QUERY(GOOGLEFINANCE($B4,""close"",TODAY()-E$1,TODAY()),""select Col2 offset 1"",0))"),68.5444262295082) -> 68.544426 | F4: =IFERROR(__xludf.DUMMYFUNCTION("AVERAGE(QUERY(GOOGLEFINANCE($B4,""close"",TODAY()-F$1,TODAY()),""select Col2 offset 1"",0))"),82.2746747967479) -> 82.274675 | G4: =IFERROR(__xludf.DUMMYFUNCTION("AVERAGE(QUERY(GOOGLEFINANCE($B4,""close"",TODAY()-G$1,TODAY()),""select Col2 offset 1"",0))"),99.8146451612902) -> 99.814645 | H4: =SQRT(D4*E4) -> 74.293816 | I4: 130 | J4: bps | K4: =H4/SQRT(255) -> 4.6524592
A5: GOLD | B5: INDEXCBOE:GVZ | C5: =IFERROR(__xludf.DUMMYFUNCTION("GOOGLEFINANCE(B5, ""price"")"),38.65) -> 38.65
A6: OIL | B6: INDEXCBOE:OVX | C6: =IFERROR(__xludf.DUMMYFUNCTION("GOOGLEFINANCE(B6, ""price"")"),90.16) -> 90.16
C13: Latest | D13: 1M_AVG | E13: 3M_AVG | F13: 1Y_AVG | G13: 5Y_AVG | H13: EST | I13: Tail
B14: EQ Risk Attr | C14: =C3*Position!$C$9/100 -> 0.19810613 | D14: =D3*Position!$C$9/100 -> 0.17389168 | E14: =E3*Position!$C$9/100 -> 0.14193941 | F14: =F3*Position!$C$9/100 -> 0.1414591 | G14: =G3*Position!$C$9/100 -> 0.14095186 | H14: =H3*Position!$C$9/100 -> 0.15710532 | I14: =I3*Position!$C$9/100 -> 0.29403508
B15: FI Risk Attr | C15: =Position!$C$10*8*C4/10000 -> 0.07591944 | D15: =Position!$C$10*8*D4/10000 -> 0.059348096 | E15: =Position!$C$10*8*E4/10000 -> 0.050517954 | F15: =Position!$C$10*8*F4/10000 -> 0.06063729 | G15: =Position!$C$10*8*G4/10000 -> 0.07356443 | H15: =Position!$C$10*8*H4/10000 -> 0.054755314 | I15: =Position!$C$10*8*I4/10000 -> 0.09581135
B18: corr=0 | C18: =SQRT(C14*C14+C15*C15) -> 0.21215514 | D18: =SQRT(D14*D14+D15*D15) -> 0.18374034 | E18: =SQRT(E14*E14+E15*E15) -> 0.15066141 | F18: =SQRT(F14*F14+F15*F15) -> 0.15390763 | G18: =SQRT(G14*G14+G15*G15) -> 0.15899419 | H18: =SQRT(H14*H14+H15*H15) -> 0.16637375 | I18: =SQRT(I14*I14+I15*I15) -> 0.30925142
B19: corr=1 | C19: =C14+C15 -> 0.27402557 | D19: =D14+D15 -> 0.23323977 | E19: =E14+E15 -> 0.19245736 | F19: =F14+F15 -> 0.20209639 | G19: =G14+G15 -> 0.21451629 | H19: =H14+H15 -> 0.21186064 | I19: =I14+I15 -> 0.38984643
